<?xml version="1.0" ?>
<robot name="turtlebot3_waffle_pi" xmlns:xacro="http://ros.org/wiki/xacro">
  <xacro:include filename="$(find turtlebot3_description)/urdf/common_properties.xacro"/>
  <xacro:include filename="$(find turtlebot3_description)/urdf/turtlebot3_waffle_pi.gazebo.xacro"/>
  <xacro:include filename="$(find turtlebot3_description)/urdf/_d435.urdf.xacro" />
  <xacro:include filename="$(find turtlebot3_description)/urdf/camera_macro.xacro"/>
  <material name="gray">
  <color rgba="0.7 0.7 0.7 1.0"/>
  </material>

  <link name="base_footprint"/>

  <joint name="base_joint" type="fixed">
    <parent link="base_footprint"/>
    <child link="base_link" />
    <origin xyz="0 0 0.010" rpy="0 0 0"/>
  </joint>

  <link name="base_link">
    <visual>
      <origin xyz="-0.064 0 0.0" rpy="0 0 0"/>
      <geometry>
        <mesh filename="package://turtlebot3_description/meshes/bases/waffle_pi_base.stl" scale="0.001 0.001 0.001"/>
      </geometry>
      <material name="light_black"/>
    </visual>

    <collision>
      <origin xyz="-0.064 0 0.047" rpy="0 0 0"/>
      <geometry>
        <box size="0.266 0.266 0.094"/>
      </geometry>
    </collision>

    <inertial>
      <origin xyz="0 0 0" rpy="0 0 0"/>
      <!-- <mass value="1.3729096e+00"/> -->
      <mass value="5.0"/>
      <inertia ixx="8.7002718e-03" ixy="-4.7576583e-05" ixz="1.1160499e-04"
               iyy="8.6195418e-03" iyz="-3.5422299e-06"
               izz="1.4612727e-02" />
    </inertial>
  </link>

  <joint name="wheel_left_joint" type="continuous">
    <dynamics damping="0.2" friction="0.1"/>
    <parent link="base_link"/>
    <child link="wheel_left_link"/>
    <origin xyz="0.0 0.144 0.023" rpy="-1.57 0 0"/>
    <axis xyz="0 0 1"/>
  </joint>

  <link name="wheel_left_link">
    <visual>
      <origin xyz="0 0 0" rpy="1.57 0 0"/>
      <geometry>
        <mesh filename="package://turtlebot3_description/meshes/wheels/left_tire.stl" scale="0.001 0.001 0.001"/>
      </geometry>
      <material name="dark"/>
    </visual>

    <collision>
      <origin xyz="0 0 0" rpy="0 0 0"/>
      <geometry>
        <cylinder length="0.018" radius="0.033"/>
      </geometry>
    </collision>

    <inertial>
      <origin xyz="0 0 0" />
      <mass value="2.8498940e-02" />
      <inertia ixx="1.1175580e-05" ixy="-4.2369783e-11" ixz="-5.9381719e-09"
               iyy="1.1192413e-05" iyz="-1.4400107e-11"
               izz="2.0712558e-05" />
      </inertial>
  </link>

  <joint name="wheel_right_joint" type="continuous">
    <dynamics damping="0.2" friction="0.1"/>
    <parent link="base_link"/>
    <child link="wheel_right_link"/>
    <origin xyz="0.0 -0.144 0.023" rpy="-1.57 0 0"/>
    <axis xyz="0 0 1"/>
  </joint>

  <link name="wheel_right_link">
    <visual>
      <origin xyz="0 0 0" rpy="1.57 0 0"/>
      <geometry>
        <mesh filename="package://turtlebot3_description/meshes/wheels/right_tire.stl" scale="0.001 0.001 0.001"/>
      </geometry>
      <material name="dark"/>
    </visual>

    <collision>
      <origin xyz="0 0 0" rpy="0 0 0"/>
      <geometry>
        <cylinder length="0.018" radius="0.033"/>
      </geometry>
    </collision>

    <inertial>
      <origin xyz="0 0 0" />
      <mass value="2.8498940e-02" />
      <inertia ixx="1.1175580e-05" ixy="-4.2369783e-11" ixz="-5.9381719e-09"
               iyy="1.1192413e-05" iyz="-1.4400107e-11"
               izz="2.0712558e-05" />
      </inertial>
  </link>

  <joint name="caster_back_right_joint" type="fixed">
    <parent link="base_link"/>
    <child link="caster_back_right_link"/>
    <origin xyz="-0.177 -0.064 -0.004" rpy="-1.57 0 0"/>
  </joint>

  <link name="caster_back_right_link">
    <collision>
      <origin xyz="0 0.001 0" rpy="0 0 0"/>
      <geometry>
        <box size="0.030 0.009 0.020"/>
      </geometry>
    </collision>

    <inertial>
      <origin xyz="0 0 0" />
      <mass value="0.005" />
      <inertia ixx="0.001" ixy="0.0" ixz="0.0"
               iyy="0.001" iyz="0.0"
               izz="0.001" />
    </inertial>
  </link>

  <joint name="caster_back_left_joint" type="fixed">
    <parent link="base_link"/>
    <child link="caster_back_left_link"/>
    <origin xyz="-0.177 0.064 -0.004" rpy="-1.57 0 0"/>
  </joint>

  <link name="caster_back_left_link">
    <collision>
      <origin xyz="0 0.001 0" rpy="0 0 0"/>
      <geometry>
        <box size="0.030 0.009 0.020"/>
      </geometry>
    </collision>

    <inertial>
      <origin xyz="0 0 0" />
      <mass value="0.005" />
      <inertia ixx="0.001" ixy="0.0" ixz="0.0"
               iyy="0.001" iyz="0.0"
               izz="0.001" />
    </inertial>
  </link>

  <joint name="imu_joint" type="fixed">
    <parent link="base_link"/>
    <child link="imu_link"/>
    <origin xyz="0.0 0 0.068" rpy="0 0 0"/>
  </joint>

  <link name="imu_link"/>

  <!-- <joint name="scan_joint" type="fixed">
    <parent link="base_link"/>
    <child link="base_scan"/>
    <origin xyz="-0.064 0 0.122" rpy="0 0 0"/>
  </joint>

  <link name="base_scan">
    <visual>
      <origin xyz="0 0 0.0" rpy="0 0 0"/>
      <geometry>
        <mesh filename="package://turtlebot3_description/meshes/sensors/lds.stl" scale="0.001 0.001 0.001"/>
      </geometry>
      <material name="dark"/>
    </visual>

    <collision>
      <origin xyz="0.015 0 -0.0065" rpy="0 0 0"/>
      <geometry>
        <cylinder length="0.0315" radius="0.055"/>
      </geometry>
    </collision>

    <inertial>
      <mass value="0.114" />
      <origin xyz="0 0 0" />
      <inertia ixx="0.001" ixy="0.0" ixz="0.0"
               iyy="0.001" iyz="0.0"
               izz="0.001" />
    </inertial>
  </link> -->
  <!-- === Livox Mid360 Lidar === -->
  <joint name="mid360_joint" type="fixed">
    <parent link="base_link"/>
    <!-- 位于原雷达位置：前方略微上方 -->
    <child link="mid360_link"/>
    <origin xyz="-0.064 0 0.122" rpy="0 0 0"/>
  </joint>

  <link name="mid360_link">
    <visual>
      <origin xyz="0 0 0" rpy="0 0 0"/>
      <geometry>
        <!-- 可自行换成实际 mesh 模型 -->
        <cylinder length="0.05" radius="0.04"/>
      </geometry>
      <material name="gray"/>
    </visual>
  </link>
  <gazebo reference="mid360_link">
    <sensor type="ray" name="laser_livox">
            <pose>0 0 0.0 0 0 0</pose>
            <visualize>true</visualize>
            <always_on>true</always_on>
            <update_rate>20</update_rate>
            <!-- This ray plgin is only for visualization. -->
            <plugin name="gazebo_ros_laser_controller" filename="liblivox_laser_simulation.so">
            <ray>
            <scan>
              <horizontal>
                <samples>100</samples>
                <resolution>1</resolution>
                <min_angle>-3.1415926535897931</min_angle>
                <max_angle>3.1415926535897931</max_angle>
              </horizontal>
              <vertical>
                <samples>50</samples>
                <resolution>1</resolution>
                <min_angle>-3.1415926535897931</min_angle>
                <max_angle>3.1415926535897931</max_angle>
              </vertical>
            </scan>
            <range>
              <min>0.1</min>
              <max>40</max>
              <resolution>1</resolution>
            </range>
            <noise>
              <type>gaussian</type>
              <mean>0.0</mean>
              <stddev>0.0</stddev>
            </noise>
            </ray>
              <visualize>false</visualize>
              <samples>20000</samples>
              <downsample>1</downsample>
              <csv_file_name>mid360-real-centr.csv</csv_file_name>
              <publish_pointcloud_type>2</publish_pointcloud_type>
              <ros_topic>/livox/lidar</ros_topic>
              <frameName>mid360_link</frameName>
            </plugin>
          </sensor>
      <!-- === End Mid360 === -->
  </gazebo>

  <gazebo reference="base_footprint">
    <sensor name='collision_sensor' type='contact'>
      <contact>
        <collision>base_footprint_fixed_joint_lump__base_link_collision</collision>
      </contact>
      <plugin name="collision_sensor" filename="libgazebo_collision_sensor.so">
        <rosDebugLevel>na</rosDebugLevel>
        <topicName>/gazebo/base_collision</topicName>
        <updateRate>20.0</updateRate>
      </plugin>
    </sensor>
  </gazebo>
  <!-- <xacro:stereo_camera_macro prefix="stereo_camera" parent="base_link" xyz="0.075 0.0 0.09"/> -->
  <!-- === Anti-slip settings for high speed === -->
  <gazebo reference="wheel_left_link">
    <mu1>20.0</mu1>
    <mu2>5.0</mu2>
    <kp>1000000.0</kp>
    <kd>10.0</kd>
    <minDepth>0.001</minDepth>
    <maxVel>0.1</maxVel>
  </gazebo>

  <gazebo reference="wheel_right_link">
    <mu1>20.0</mu1>
    <mu2>5.0</mu2>
    <kp>1000000.0</kp>
    <kd>10.0</kd>
    <minDepth>0.001</minDepth>
    <maxVel>0.1</maxVel>
  </gazebo>
  <xacro:sensor_d435 name="camera" topics_ns="camera" parent="base_link" publish_pointcloud="true">
    <origin xyz="0.075 0.0 0.09" rpy="0 0 0" />
  </xacro:sensor_d435>

</robot>
